[0m10:42:00.787453 [debug] [MainThread]: Sending event: {'category': 'dbt', 'action': 'invocation', 'label': 'start', 'context': [<snowplow_tracker.self_describing_json.SelfDescribingJson object at 0x000002B76F9CF0E0>, <snowplow_tracker.self_describing_json.SelfDescribingJson object at 0x000002B770D63D90>, <snowplow_tracker.self_describing_json.SelfDescribingJson object at 0x000002B770D63B10>]}


============================== 10:42:00.791252 | 16f7b546-c9ea-4da5-a347-4790f5b53f66 ==============================
[0m10:42:00.791252 [info ] [MainThread]: Running with dbt=1.10.2
[0m10:42:00.791856 [debug] [MainThread]: running dbt with arguments {'printer_width': '80', 'indirect_selection': 'eager', 'write_json': 'True', 'log_cache_events': 'False', 'partial_parse': 'True', 'cache_selected_only': 'False', 'profiles_dir': 'C:\\Users\\Admin\\.dbt', 'fail_fast': 'False', 'debug': 'False', 'log_path': 'logs', 'warn_error': 'None', 'version_check': 'True', 'use_colors': 'True', 'use_experimental_parser': 'False', 'no_print': 'None', 'quiet': 'False', 'empty': 'None', 'warn_error_options': 'WarnErrorOptionsV2(error=[], warn=[], silence=[])', 'introspect': 'True', 'invocation_command': 'dbt ', 'log_format': 'default', 'target_path': 'None', 'static_parser': 'True', 'send_anonymous_usage_stats': 'True'}
[0m10:42:00.793162 [error] [MainThread]: Encountered an error:
Runtime Error
  No dbt_project.yml found at expected path d:\Project_DE\Transform\dbt_project.yml
  Verify that each entry within packages.yml (and their transitive dependencies) contains a file named dbt_project.yml
  
[0m10:42:00.794284 [debug] [MainThread]: Command `cli deps` failed at 10:42:00.794129 after 0.14 seconds
[0m10:42:00.794713 [debug] [MainThread]: Sending event: {'category': 'dbt', 'action': 'invocation', 'label': 'end', 'context': [<snowplow_tracker.self_describing_json.SelfDescribingJson object at 0x000002B770D5A2C0>, <snowplow_tracker.self_describing_json.SelfDescribingJson object at 0x000002B770C5E450>, <snowplow_tracker.self_describing_json.SelfDescribingJson object at 0x000002B770DD0160>]}
[0m10:42:00.795066 [debug] [MainThread]: Flushing usage events
[0m10:42:01.864989 [debug] [MainThread]: An error was encountered while trying to flush usage events
[0m14:07:09.331583 [debug] [MainThread]: Sending event: {'category': 'dbt', 'action': 'invocation', 'label': 'start', 'context': [<snowplow_tracker.self_describing_json.SelfDescribingJson object at 0x0000019DE05FF230>, <snowplow_tracker.self_describing_json.SelfDescribingJson object at 0x0000019DE19A3D90>, <snowplow_tracker.self_describing_json.SelfDescribingJson object at 0x0000019DE19A39D0>]}


============================== 14:07:09.338090 | 85238b28-1a54-4b7a-be45-fa1d5e97a673 ==============================
[0m14:07:09.338090 [info ] [MainThread]: Running with dbt=1.10.2
[0m14:07:09.339171 [debug] [MainThread]: running dbt with arguments {'printer_width': '80', 'indirect_selection': 'eager', 'write_json': 'True', 'log_cache_events': 'False', 'partial_parse': 'True', 'cache_selected_only': 'False', 'profiles_dir': 'C:\\Users\\Admin\\.dbt', 'version_check': 'True', 'warn_error': 'None', 'log_path': 'logs', 'fail_fast': 'False', 'debug': 'False', 'use_colors': 'True', 'use_experimental_parser': 'False', 'no_print': 'None', 'quiet': 'False', 'empty': 'False', 'warn_error_options': 'WarnErrorOptionsV2(error=[], warn=[], silence=[])', 'introspect': 'True', 'static_parser': 'True', 'log_format': 'default', 'target_path': 'None', 'invocation_command': 'dbt run --select stg_variants.sql', 'send_anonymous_usage_stats': 'True'}
[0m14:07:09.340019 [error] [MainThread]: Encountered an error:
Runtime Error
  No dbt_project.yml found at expected path D:\Project_DE\dbt_project.yml
  Verify that each entry within packages.yml (and their transitive dependencies) contains a file named dbt_project.yml
  
[0m14:07:09.341891 [debug] [MainThread]: Command `dbt run` failed at 14:07:09.341718 after 0.24 seconds
[0m14:07:09.342358 [debug] [MainThread]: Sending event: {'category': 'dbt', 'action': 'invocation', 'label': 'end', 'context': [<snowplow_tracker.self_describing_json.SelfDescribingJson object at 0x0000019DE19A63F0>, <snowplow_tracker.self_describing_json.SelfDescribingJson object at 0x0000019DE18A28D0>, <snowplow_tracker.self_describing_json.SelfDescribingJson object at 0x0000019DE1A1C380>]}
[0m14:07:09.342950 [debug] [MainThread]: Flushing usage events
[0m14:07:10.413492 [debug] [MainThread]: An error was encountered while trying to flush usage events
[0m10:06:26.871508 [debug] [MainThread]: Sending event: {'category': 'dbt', 'action': 'invocation', 'label': 'start', 'context': [<snowplow_tracker.self_describing_json.SelfDescribingJson object at 0x00000205A1B1F230>, <snowplow_tracker.self_describing_json.SelfDescribingJson object at 0x00000205A2ECBD90>, <snowplow_tracker.self_describing_json.SelfDescribingJson object at 0x00000205A2ECB9D0>]}


============================== 10:06:26.875762 | 99530979-81a0-43c1-8668-bcaf2769ec3e ==============================
[0m10:06:26.875762 [info ] [MainThread]: Running with dbt=1.10.2
[0m10:06:26.876682 [debug] [MainThread]: running dbt with arguments {'printer_width': '80', 'indirect_selection': 'eager', 'log_cache_events': 'False', 'write_json': 'True', 'partial_parse': 'True', 'cache_selected_only': 'False', 'warn_error': 'None', 'fail_fast': 'False', 'debug': 'False', 'log_path': 'logs', 'profiles_dir': 'C:\\Users\\Admin\\.dbt', 'version_check': 'True', 'use_colors': 'True', 'use_experimental_parser': 'False', 'no_print': 'None', 'quiet': 'False', 'empty': 'False', 'warn_error_options': 'WarnErrorOptionsV2(error=[], warn=[], silence=[])', 'static_parser': 'True', 'invocation_command': 'dbt run --select dim_currency.sql', 'log_format': 'default', 'target_path': 'None', 'introspect': 'True', 'send_anonymous_usage_stats': 'True'}
[0m10:06:26.877400 [error] [MainThread]: Encountered an error:
Runtime Error
  No dbt_project.yml found at expected path D:\Project_DE\dbt_project.yml
  Verify that each entry within packages.yml (and their transitive dependencies) contains a file named dbt_project.yml
  
[0m10:06:26.878676 [debug] [MainThread]: Command `dbt run` failed at 10:06:26.878545 after 0.18 seconds
[0m10:06:26.879016 [debug] [MainThread]: Sending event: {'category': 'dbt', 'action': 'invocation', 'label': 'end', 'context': [<snowplow_tracker.self_describing_json.SelfDescribingJson object at 0x00000205A2EC63F0>, <snowplow_tracker.self_describing_json.SelfDescribingJson object at 0x00000205A2DC28D0>, <snowplow_tracker.self_describing_json.SelfDescribingJson object at 0x00000205A3F10380>]}
[0m10:06:26.879372 [debug] [MainThread]: Flushing usage events
[0m10:06:28.336313 [debug] [MainThread]: An error was encountered while trying to flush usage events
[0m11:33:23.146747 [debug] [MainThread]: Sending event: {'category': 'dbt', 'action': 'invocation', 'label': 'start', 'context': [<snowplow_tracker.self_describing_json.SelfDescribingJson object at 0x0000023627B35160>, <snowplow_tracker.self_describing_json.SelfDescribingJson object at 0x0000023628800050>, <snowplow_tracker.self_describing_json.SelfDescribingJson object at 0x0000023628E37D90>]}


============================== 11:33:23.155448 | bc7d4626-c29c-4e81-9cc3-5bbed2518099 ==============================
[0m11:33:23.155448 [info ] [MainThread]: Running with dbt=1.10.2
[0m11:33:23.156391 [debug] [MainThread]: running dbt with arguments {'printer_width': '80', 'indirect_selection': 'eager', 'log_cache_events': 'False', 'write_json': 'True', 'partial_parse': 'True', 'cache_selected_only': 'False', 'profiles_dir': 'C:\\Users\\Admin\\.dbt', 'debug': 'False', 'warn_error': 'None', 'log_path': 'logs', 'fail_fast': 'False', 'version_check': 'True', 'use_colors': 'True', 'use_experimental_parser': 'False', 'no_print': 'None', 'quiet': 'False', 'empty': 'False', 'log_format': 'default', 'invocation_command': 'dbt run --full-refresh', 'warn_error_options': 'WarnErrorOptionsV2(error=[], warn=[], silence=[])', 'introspect': 'True', 'target_path': 'None', 'static_parser': 'True', 'send_anonymous_usage_stats': 'True'}
[0m11:33:23.156952 [error] [MainThread]: Encountered an error:
Runtime Error
  No dbt_project.yml found at expected path D:\project_de\dbt_project.yml
  Verify that each entry within packages.yml (and their transitive dependencies) contains a file named dbt_project.yml
  
[0m11:33:23.158139 [debug] [MainThread]: Command `dbt run` failed at 11:33:23.158026 after 0.22 seconds
[0m11:33:23.158445 [debug] [MainThread]: Sending event: {'category': 'dbt', 'action': 'invocation', 'label': 'end', 'context': [<snowplow_tracker.self_describing_json.SelfDescribingJson object at 0x0000023628CD3A80>, <snowplow_tracker.self_describing_json.SelfDescribingJson object at 0x0000023629E44B90>, <snowplow_tracker.self_describing_json.SelfDescribingJson object at 0x0000023628CE4F30>]}
[0m11:33:23.158701 [debug] [MainThread]: Flushing usage events
[0m11:33:24.265529 [debug] [MainThread]: An error was encountered while trying to flush usage events
